Workbook

Sheet Súpis dlhov
A1: Súpis pohľadávok a výpočet úroku z omeškania
A3: Dátum výpočtu (ku dňu) | B3: =TODAY() -> 46306 | C3: Predvolene dnešný dátum. Pre výpočet k pevnému dňu (napr. ku dňu podania žaloby) prepíšte dátumom.
A4: Úroková sadzba ročne (p. a.) | B4: 0.1 | C4: Zadané používateľom: 10 % ročne.
A5: Kapitalizácia úroku každých (mesiacov) | B5: 3 | C5: Zadané používateľom: úrok sa pripisuje k istine každé 3 mesiace.
A6: Sadzba za jedno obdobie | B6: =B4*B5/12 -> 0.025 | C6: Vypočítané: 10 % × 3 / 12 = 2,5 % za štvrťrok.
A8: Legenda: žlté bunky s modrým písmom vyplňte (dlžník, titul, istina, dátum, úročiť, stav, poznámka). Biele bunky sú vzorce – neprepisujte ich. Riadky 11–22 ukazujú formát vyplnenia (dátum DD.MM.RRRR, suma v €).
A9: Metóda: za každé ukončené 3-mesačné obdobie od dátumu splatnosti sa úrok pripočíta k istine (zložené úročenie). Za nedokončené bežné obdobie sa počíta jednoduchý úrok z kapitalizovanej istiny pomerne podľa dní (rok = 365 dní). Pri „Úročiť = nie“ sa úrok nepočíta a dlžná suma = istina.
A10: Dlžník | B10: Právny titul / popis | C10: Istina (€) | D10: Dátum, od ktorého plynie úrok | E10: Úročiť (áno/nie) | F10: Stav | G10: Dni omeškania | H10: Ukončené obdobia (3 mes.) | I10: Dni v bežnom období | J10: Istina po kapitalizácii (€) | K10: Úrok celkom (€) | L10: Dlžná suma celkom (€) | M10: Poznámka
A11: Štefan Nagy Bačo | B11: Pôžička – BauHausEurope s.r.o. pre PSPSK s.r.o. | C11: 50000 | D11: 45471 | E11: áno | F11: otvorené | G11: =IF(OR($A11="",$D11="",$C11=""),"",MAX(0,$B$3-$D11)) -> 835 | H11: =IF($G11="","",IF(OR($E11="nie",$B$3<=$D11),0,INT(DATEDIF($D11,$B$3,"m")/$B$5))) -> 9 | I11: =IF($H11="","",IF($E11="nie",0,MAX(0,$B$3-EDATE($D11,$H11*$B$5)))) -> 13 | J11: =IF($H11="","",$C11*(1+$B$6)^$H11) -> 62443.148 | K11: =IF($H11="","",IF($E11="nie",0,$J11*(1+$B$4*$I11/365)-$C11)) -> 12665.549 | L11: =IF($H11="","",$C11+$K11) -> 62665.549
A12: Štefan Nagy Bačo | B12: Pôžička v hotovosti v SL (december 2024) | C12: 5000 | D12: 45657 | E12: áno | F12: otvorené | G12: =IF(OR($A12="",$D12="",$C12=""),"",MAX(0,$B$3-$D12)) -> 649 | H12: =IF($G12="","",IF(OR($E12="nie",$B$3<=$D12),0,INT(DATEDIF($D12,$B$3,"m")/$B$5))) -> 7 | I12: =IF($H12="","",IF($E12="nie",0,MAX(0,$B$3-EDATE($D12,$H12*$B$5)))) -> 11 | J12: =IF($H12="","",$C12*(1+$B$6)^$H12) -> 5943.4288 | K12: =IF($H12="","",IF($E12="nie",0,$J12*(1+$B$4*$I12/365)-$C12)) -> 961.34047 | L12: =IF($H12="","",$C12+$K12) -> 5961.3405 | M12: presný deň neznámy – použitý 31.12.2024, DOPLŇTE
A13: Štefan Nagy Bačo | B13: Nevrátená suma (11/2025) | C13: 5000 | D13: 45991 | E13: áno | F13: otvorené | G13: =IF(OR($A13="",$D13="",$C13=""),"",MAX(0,$B$3-$D13)) -> 315 | H13: =IF($G13="","",IF(OR($E13="nie",$B$3<=$D13),0,INT(DATEDIF($D13,$B$3,"m")/$B$5))) -> 3 | I13: =IF($H13="","",IF($E13="nie",0,MAX(0,$B$3-EDATE($D13,$H13*$B$5)))) -> 42 | J13: =IF($H13="","",$C13*(1+$B$6)^$H13) -> 5384.4531 | K13: =IF($H13="","",IF($E13="nie",0,$J13*(1+$B$4*$I13/365)-$C13)) -> 446.41122 | L13: =IF($H13="","",$C13+$K13) -> 5446.4112 | M13: presný deň neznámy – použitý 30.11.2025, DOPLŇTE
A14: Štefan Nagy Bačo | B14: Dvere – nedodané | C14: 10000 | D14: 45830 | E14: áno | F14: otvorené | G14: =IF(OR($A14="",$D14="",$C14=""),"",MAX(0,$B$3-$D14)) -> 476 | H14: =IF($G14="","",IF(OR($E14="nie",$B$3<=$D14),0,INT(DATEDIF($D14,$B$3,"m")/$B$5))) -> 5 | I14: =IF($H14="","",IF($E14="nie",0,MAX(0,$B$3-EDATE($D14,$H14*$B$5)))) -> 19 | J14: =IF($H14="","",$C14*(1+$B$6)^$H14) -> 11314.082 | K14: =IF($H14="","",IF($E14="nie",0,$J14*(1+$B$4*$I14/365)-$C14)) -> 1372.9774 | L14: =IF($H14="","",$C14+$K14) -> 11372.977
A15: Štefan Nagy Bačo | B15: Dvere – ďalšia platba | C15: 5000 | D15: 45854 | E15: áno | F15: otvorené | G15: =IF(OR($A15="",$D15="",$C15=""),"",MAX(0,$B$3-$D15)) -> 452 | H15: =IF($G15="","",IF(OR($E15="nie",$B$3<=$D15),0,INT(DATEDIF($D15,$B$3,"m")/$B$5))) -> 4 | I15: =IF($H15="","",IF($E15="nie",0,MAX(0,$B$3-EDATE($D15,$H15*$B$5)))) -> 87 | J15: =IF($H15="","",$C15*(1+$B$6)^$H15) -> 5519.0645 | K15: =IF($H15="","",IF($E15="nie",0,$J15*(1+$B$4*$I15/365)-$C15)) -> 650.61476 | L15: =IF($H15="","",$C15+$K15) -> 5650.6148
A16: Štefan Nagy Bačo | B16: Dvere – ďalšia platba | C16: 20000 | D16: 45916 | E16: áno | F16: otvorené | G16: =IF(OR($A16="",$D16="",$C16=""),"",MAX(0,$B$3-$D16)) -> 390 | H16: =IF($G16="","",IF(OR($E16="nie",$B$3<=$D16),0,INT(DATEDIF($D16,$B$3,"m")/$B$5))) -> 4 | I16: =IF($H16="","",IF($E16="nie",0,MAX(0,$B$3-EDATE($D16,$H16*$B$5)))) -> 25 | J16: =IF($H16="","",$C16*(1+$B$6)^$H16) -> 22076.258 | K16: =IF($H16="","",IF($E16="nie",0,$J16*(1+$B$4*$I16/365)-$C16)) -> 2227.4651 | L16: =IF($H16="","",$C16+$K16) -> 22227.465
A17: Štefan Nagy Bačo | B17: Prenájom vozidla | C17: 739.23 | D17: 45798 | E17: áno | F17: otvorené | G17: =IF(OR($A17="",$D17="",$C17=""),"",MAX(0,$B$3-$D17)) -> 508 | H17: =IF($G17="","",IF(OR($E17="nie",$B$3<=$D17),0,INT(DATEDIF($D17,$B$3,"m")/$B$5))) -> 5 | I17: =IF($H17="","",IF($E17="nie",0,MAX(0,$B$3-EDATE($D17,$H17*$B$5)))) -> 51 | J17: =IF($H17="","",$C17*(1+$B$6)^$H17) -> 836.37089 | K17: =IF($H17="","",IF($E17="nie",0,$J17*(1+$B$4*$I17/365)-$C17)) -> 108.82717 | L17: =IF($H17="","",$C17+$K17) -> 848.05717 | M17: dlžník neuvedený – priradené Bačovi, v prípade potreby zmeňte meno
A18: Štefan Nagy Bačo | B18: S-Class – uhradený doplatok | C18: 9692.15 | D18: 45792 | E18: áno | F18: otvorené | G18: =IF(OR($A18="",$D18="",$C18=""),"",MAX(0,$B$3-$D18)) -> 514 | H18: =IF($G18="","",IF(OR($E18="nie",$B$3<=$D18),0,INT(DATEDIF($D18,$B$3,"m")/$B$5))) -> 5 | I18: =IF($H18="","",IF($E18="nie",0,MAX(0,$B$3-EDATE($D18,$H18*$B$5)))) -> 57 | J18: =IF($H18="","",$C18*(1+$B$6)^$H18) -> 10965.778 | K18: =IF($H18="","",IF($E18="nie",0,$J18*(1+$B$4*$I18/365)-$C18)) -> 1444.8745 | L18: =IF($H18="","",$C18+$K18) -> 11137.025 | M18: dlžník neuvedený – priradené Bačovi, v prípade potreby zmeňte meno
A19: Lukáš Cisco | B19: Prvá vlna (2022), cca | C19: 40000 | D19: 44926 | E19: áno | F19: otvorené | G19: =IF(OR($A19="",$D19="",$C19=""),"",MAX(0,$B$3-$D19)) -> 1380 | H19: =IF($G19="","",IF(OR($E19="nie",$B$3<=$D19),0,INT(DATEDIF($D19,$B$3,"m")/$B$5))) -> 15 | I19: =IF($H19="","",IF($E19="nie",0,MAX(0,$B$3-EDATE($D19,$H19*$B$5)))) -> 11 | J19: =IF($H19="","",$C19*(1+$B$6)^$H19) -> 57931.927 | K19: =IF($H19="","",IF($E19="nie",0,$J19*(1+$B$4*$I19/365)-$C19)) -> 18106.516 | L19: =IF($H19="","",$C19+$K19) -> 58106.516 | M19: suma približná, presný deň neznámy – použitý 31.12.2022, DOPLŇTE
A20: Lukáš Cisco | B20: Druhá vlna (2024) | C20: 30000 | D20: 45657 | E20: áno | F20: otvorené | G20: =IF(OR($A20="",$D20="",$C20=""),"",MAX(0,$B$3-$D20)) -> 649 | H20: =IF($G20="","",IF(OR($E20="nie",$B$3<=$D20),0,INT(DATEDIF($D20,$B$3,"m")/$B$5))) -> 7 | I20: =IF($H20="","",IF($E20="nie",0,MAX(0,$B$3-EDATE($D20,$H20*$B$5)))) -> 11 | J20: =IF($H20="","",$C20*(1+$B$6)^$H20) -> 35660.573 | K20: =IF($H20="","",IF($E20="nie",0,$J20*(1+$B$4*$I20/365)-$C20)) -> 5768.0428 | L20: =IF($H20="","",$C20+$K20) -> 35768.043 | M20: presný deň neznámy – použitý 31.12.2024, DOPLŇTE
A21: Lukáš Cisco | B21: Tretia vlna (2025) | C21: 21000 | D21: 46022 | E21: áno | F21: otvorené | G21: =IF(OR($A21="",$D21="",$C21=""),"",MAX(0,$B$3-$D21)) -> 284 | H21: =IF($G21="","",IF(OR($E21="nie",$B$3<=$D21),0,INT(DATEDIF($D21,$B$3,"m")/$B$5))) -> 3 | I21: =IF($H21="","",IF($E21="nie",0,MAX(0,$B$3-EDATE($D21,$H21*$B$5)))) -> 11 | J21: =IF($H21="","",$C21*(1+$B$6)^$H21) -> 22614.703 | K21: =IF($H21="","",IF($E21="nie",0,$J21*(1+$B$4*$I21/365)-$C21)) -> 1682.857 | L21: =IF($H21="","",$C21+$K21) -> 22682.857 | M21: presný deň neznámy – použitý 31.12.2025, DOPLŇTE
A22: Lukáš Cisco | B22: Daň za rok 2025 | C22: 61907 | D22: 46022 | E22: áno | F22: otvorené | G22: =IF(OR($A22="",$D22="",$C22=""),"",MAX(0,$B$3-$D22)) -> 284 | H22: =IF($G22="","",IF(OR($E22="nie",$B$3<=$D22),0,INT(DATEDIF($D22,$B$3,"m")/$B$5))) -> 3 | I22: =IF($H22="","",IF($E22="nie",0,MAX(0,$B$3-EDATE($D22,$H22*$B$5)))) -> 11 | J22: =IF($H22="","",$C22*(1+$B$6)^$H22) -> 66667.068 | K22: =IF($H22="","",IF($E22="nie",0,$J22*(1+$B$4*$I22/365)-$C22)) -> 4960.9824 | L22: =IF($H22="","",$C22+$K22) -> 66867.982 | M22: dátum splatnosti neznámy – použitý 31.12.2025, DOPLŇTE
A23: Baláž | E23: nie | F23: otvorené | G23: =IF(OR($A23="",$D23="",$C23=""),"",MAX(0,$B$3-$D23)) | H23: =IF($G23="","",IF(OR($E23="nie",$B$3<=$D23),0,INT(DATEDIF($D23,$B$3,"m")/$B$5))) | I23: =IF($H23="","",IF($E23="nie",0,MAX(0,$B$3-EDATE($D23,$H23*$B$5)))) | J23: =IF($H23="","",$C23*(1+$B$6)^$H23) | K23: =IF($H23="","",IF($E23="nie",0,$J23*(1+$B$4*$I23/365)-$C23)) | L23: =IF($H23="","",$C23+$K23) | M23: bez úroku – doplňte istinu a dátum
A24: YQ House | E24: áno | F24: otvorené | G24: =IF(OR($A24="",$D24="",$C24=""),"",MAX(0,$B$3-$D24)) | H24: =IF($G24="","",IF(OR($E24="nie",$B$3<=$D24),0,INT(DATEDIF($D24,$B$3,"m")/$B$5))) | I24: =IF($H24="","",IF($E24="nie",0,MAX(0,$B$3-EDATE($D24,$H24*$B$5)))) | J24: =IF($H24="","",$C24*(1+$B$6)^$H24) | K24: =IF($H24="","",IF($E24="nie",0,$J24*(1+$B$4*$I24/365)-$C24)) | L24: =IF($H24="","",$C24+$K24) | M24: súvisí so Štefanom – doplňte istinu a dátum
G25: =IF(OR($A25="",$D25="",$C25=""),"",MAX(0,$B$3-$D25)) | H25: =IF($G25="","",IF(OR($E25="nie",$B$3<=$D25),0,INT(DATEDIF($D25,$B$3,"m")/$B$5))) | I25: =IF($H25="","",IF($E25="nie",0,MAX(0,$B$3-EDATE($D25,$H25*$B$5)))) | J25: =IF($H25="","",$C25*(1+$B$6)^$H25) | K25: =IF($H25="","",IF($E25="nie",0,$J25*(1+$B$4*$I25/365)-$C25)) | L25: =IF($H25="","",$C25+$K25)
G26: =IF(OR($A26="",$D26="",$C26=""),"",MAX(0,$B$3-$D26)) | H26: =IF($G26="","",IF(OR($E26="nie",$B$3<=$D26),0,INT(DATEDIF($D26,$B$3,"m")/$B$5))) | I26: =IF($H26="","",IF($E26="nie",0,MAX(0,$B$3-EDATE($D26,$H26*$B$5)))) | J26: =IF($H26="","",$C26*(1+$B$6)^$H26) | K26: =IF($H26="","",IF($E26="nie",0,$J26*(1+$B$4*$I26/365)-$C26)) | L26: =IF($H26="","",$C26+$K26)
G27: =IF(OR($A27="",$D27="",$C27=""),"",MAX(0,$B$3-$D27)) | H27: =IF($G27="","",IF(OR($E27="nie",$B$3<=$D27),0,INT(DATEDIF($D27,$B$3,"m")/$B$5))) | I27: =IF($H27="","",IF($E27="nie",0,MAX(0,$B$3-EDATE($D27,$H27*$B$5)))) | J27: =IF($H27="","",$C27*(1+$B$6)^$H27) | K27: =IF($H27="","",IF($E27="nie",0,$J27*(1+$B$4*$I27/365)-$C27)) | L27: =IF($H27="","",$C27+$K27)
G28: =IF(OR($A28="",$D28="",$C28=""),"",MAX(0,$B$3-$D28)) | H28: =IF($G28="","",IF(OR($E28="nie",$B$3<=$D28),0,INT(DATEDIF($D28,$B$3,"m")/$B$5))) | I28: =IF($H28="","",IF($E28="nie",0,MAX(0,$B$3-EDATE($D28,$H28*$B$5)))) | J28: =IF($H28="","",$C28*(1+$B$6)^$H28) | K28: =IF($H28="","",IF($E28="nie",0,$J28*(1+$B$4*$I28/365)-$C28)) | L28: =IF($H28="","",$C28+$K28)
G29: =IF(OR($A29="",$D29="",$C29=""),"",MAX(0,$B$3-$D29)) | H29: =IF($G29="","",IF(OR($E29="nie",$B$3<=$D29),0,INT(DATEDIF($D29,$B$3,"m")/$B$5))) | I29: =IF($H29="","",IF($E29="nie",0,MAX(0,$B$3-EDATE($D29,$H29*$B$5)))) | J29: =IF($H29="","",$C29*(1+$B$6)^$H29) | K29: =IF($H29="","",IF($E29="nie",0,$J29*(1+$B$4*$I29/365)-$C29)) | L29: =IF($H29="","",$C29+$K29)
G30: =IF(OR($A30="",$D30="",$C30=""),"",MAX(0,$B$3-$D30)) | H30: =IF($G30="","",IF(OR($E30="nie",$B$3<=$D30),0,INT(DATEDIF($D30,$B$3,"m")/$B$5))) | I30: =IF($H30="","",IF($E30="nie",0,MAX(0,$B$3-EDATE($D30,$H30*$B$5)))) | J30: =IF($H30="","",$C30*(1+$B$6)^$H30) | K30: =IF($H30="","",IF($E30="nie",0,$J30*(1+$B$4*$I30/365)-$C30)) | L30: =IF($H30="","",$C30+$K30)
G31: =IF(OR($A31="",$D31="",$C31=""),"",MAX(0,$B$3-$D31)) | H31: =IF($G31="","",IF(OR($E31="nie",$B$3<=$D31),0,INT(DATEDIF($D31,$B$3,"m")/$B$5))) | I31: =IF($H31="","",IF($E31="nie",0,MAX(0,$B$3-EDATE($D31,$H31*$B$5)))) | J31: =IF($H31="","",$C31*(1+$B$6)^$H31) | K31: =IF($H31="","",IF($E31="nie",0,$J31*(1+$B$4*$I31/365)-$C31)) | L31: =IF($H31="","",$C31+$K31)
G32: =IF(OR($A32="",$D32="",$C32=""),"",MAX(0,$B$3-$D32)) | H32: =IF($G32="","",IF(OR($E32="nie",$B$3<=$D32),0,INT(DATEDIF($D32,$B$3,"m")/$B$5))) | I32: =IF($H32="","",IF($E32="nie",0,MAX(0,$B$3-EDATE($D32,$H32*$B$5)))) | J32: =IF($H32="","",$C32*(1+$B$6)^$H32) | K32: =IF($H32="","",IF($E32="nie",0,$J32*(1+$B$4*$I32/365)-$C32)) | L32: =IF($H32="","",$C32+$K32)
G33: =IF(OR($A33="",$D33="",$C33=""),"",MAX(0,$B$3-$D33)) | H33: =IF($G33="","",IF(OR($E33="nie",$B$3<=$D33),0,INT(DATEDIF($D33,$B$3,"m")/$B$5))) | I33: =IF($H33="","",IF($E33="nie",0,MAX(0,$B$3-EDATE($D33,$H33*$B$5)))) | J33: =IF($H33="","",$C33*(1+$B$6)^$H33) | K33: =IF($H33="","",IF($E33="nie",0,$J33*(1+$B$4*$I33/365)-$C33)) | L33: =IF($H33="","",$C33+$K33)
G34: =IF(OR($A34="",$D34="",$C34=""),"",MAX(0,$B$3-$D34)) | H34: =IF($G34="","",IF(OR($E34="nie",$B$3<=$D34),0,INT(DATEDIF($D34,$B$3,"m")/$B$5))) | I34: =IF($H34="","",IF($E34="nie",0,MAX(0,$B$3-EDATE($D34,$H34*$B$5)))) | J34: =IF($H34="","",$C34*(1+$B$6)^$H34) | K34: =IF($H34="","",IF($E34="nie",0,$J34*(1+$B$4*$I34/365)-$C34)) | L34: =IF($H34="","",$C34+$K34)
G35: =IF(OR($A35="",$D35="",$C35=""),"",MAX(0,$B$3-$D35)) | H35: =IF($G35="","",IF(OR($E35="nie",$B$3<=$D35),0,INT(DATEDIF($D35,$B$3,"m")/$B$5))) | I35: =IF($H35="","",IF($E35="nie",0,MAX(0,$B$3-EDATE($D35,$H35*$B$5)))) | J35: =IF($H35="","",$C35*(1+$B$6)^$H35) | K35: =IF($H35="","",IF($E35="nie",0,$J35*(1+$B$4*$I35/365)-$C35)) | L35: =IF($H35="","",$C35+$K35)
G36: =IF(OR($A36="",$D36="",$C36=""),"",MAX(0,$B$3-$D36)) | H36: =IF($G36="","",IF(OR($E36="nie",$B$3<=$D36),0,INT(DATEDIF($D36,$B$3,"m")/$B$5))) | I36: =IF($H36="","",IF($E36="nie",0,MAX(0,$B$3-EDATE($D36,$H36*$B$5)))) | J36: =IF($H36="","",$C36*(1+$B$6)^$H36) | K36: =IF($H36="","",IF($E36="nie",0,$J36*(1+$B$4*$I36/365)-$C36)) | L36: =IF($H36="","",$C36+$K36)
... G60: =IF(OR($A60="",$D60="",$C60=""),"",MAX(0,$B$3-$D60)) | H60: =IF($G60="","",IF(OR($E60="nie",$B$3<=$D60),0,INT(DATEDIF($D60,$B$3,"m")/$B$5))) | I60: =IF($H60="","",IF($E60="nie",0,MAX(0,$B$3-EDATE($D60,$H60*$B$5)))) | J60: =IF($H60="","",$C60*(1+$B$6)^$H60) | K60: =IF($H60="","",IF($E60="nie",0,$J60*(1+$B$4*$I60/365)-$C60)) | L60: =IF($H60="","",$C60+$K60)
A62: SPOLU – otvorené pohľadávky | C62: =SUMIF($F$11:$F$60,"otvorené",C11:C60) -> 258338.38 | F62: počet: | G62: =COUNTIFS($F$11:$F$60,"otvorené",$C$11:$C$60,"<>") -> 12 | K62: =SUMIF($F$11:$F$60,"otvorené",K11:K60) -> 50396.458 | L62: =SUMIF($F$11:$F$60,"otvorené",L11:L60) -> 308734.84
A64: Súhrn podľa dlžníka (len otvorené pohľadávky) | M64: Pri novom dlžníkovi doplňte meno do stĺpca A v tomto súhrne – vzorce sú SUMIFS.
A65: Dlžník | C65: Istina (€) | K65: Úrok celkom (€) | L65: Dlžná suma celkom (€)
A66: Štefan Nagy Bačo | C66: =SUMIFS(C$11:C$60,$A$11:$A$60,$A66,$F$11:$F$60,"otvorené") -> 105431.38 | K66: =SUMIFS(K$11:K$60,$A$11:$A$60,$A66,$F$11:$F$60,"otvorené") -> 19878.059 | L66: =SUMIFS(L$11:L$60,$A$11:$A$60,$A66,$F$11:$F$60,"otvorené") -> 125309.44
A67: Lukáš Cisco | C67: =SUMIFS(C$11:C$60,$A$11:$A$60,$A67,$F$11:$F$60,"otvorené") -> 152907 | K67: =SUMIFS(K$11:K$60,$A$11:$A$60,$A67,$F$11:$F$60,"otvorené") -> 30518.398 | L67: =SUMIFS(L$11:L$60,$A$11:$A$60,$A67,$F$11:$F$60,"otvorené") -> 183425.4
...

Sheet Detail výpočtu
A1: Detailný rozpis úročenia pre jedného dlžníka (podklad do výzvy / žaloby)
A3: Dlžník (vyberte zo zoznamu) | B3: Štefan Nagy Bačo | C3: Zoznam sa plní z hárka „Súpis dlhov“. Rozpis zobrazí max. 80 ukončených období (20 rokov).
A4: Istina (€) | B4: =INDEX('Súpis dlhov'!$C$11:$C$60,MATCH($B$3,'Súpis dlhov'!$A$11:$A$60,0)) -> 50000
A5: Úrok plynie od | B5: =INDEX('Súpis dlhov'!$D$11:$D$60,MATCH($B$3,'Súpis dlhov'!$A$11:$A$60,0)) -> 45471
A6: Dátum výpočtu | B6: ='Súpis dlhov'!$B$3 -> 46306
A7: Ukončené obdobia | B7: =INDEX('Súpis dlhov'!$H$11:$H$60,MATCH($B$3,'Súpis dlhov'!$A$11:$A$60,0)) -> 9
A8: Sadzba za obdobie | B8: =IF($B$9="nie",0,'Súpis dlhov'!$B$6) -> 0.025
A9: Úročiť | B9: =INDEX('Súpis dlhov'!$E$11:$E$60,MATCH($B$3,'Súpis dlhov'!$A$11:$A$60,0)) -> áno
A11: Obdobie č. | B11: Od | C11: Do | D11: Istina na začiatku (€) | E11: Úrok za obdobie (€) | F11: Istina na konci – kapitalizovaná (€)
A12: =IF(1<=$B$7,1,"") -> 1 | B12: =IF($A12="","",EDATE($B$5,($A12-1)*'Súpis dlhov'!$B$5)) -> 45471 | C12: =IF($A12="","",EDATE($B$5,$A12*'Súpis dlhov'!$B$5)) -> 45563 | D12: =IF($A12="","",$B$4) -> 50000 | E12: =IF($A12="","",$D12*$B$8) -> 1250 | F12: =IF($A12="","",$D12+$E12) -> 51250
A13: =IF(2<=$B$7,2,"") -> 2 | B13: =IF($A13="","",EDATE($B$5,($A13-1)*'Súpis dlhov'!$B$5)) -> 45563 | C13: =IF($A13="","",EDATE($B$5,$A13*'Súpis dlhov'!$B$5)) -> 45654 | D13: =IF($A13="","",$F12) -> 51250 | E13: =IF($A13="","",$D13*$B$8) -> 1281.25 | F13: =IF($A13="","",$D13+$E13) -> 52531.25
A14: =IF(3<=$B$7,3,"") -> 3 | B14: =IF($A14="","",EDATE($B$5,($A14-1)*'Súpis dlhov'!$B$5)) -> 45654 | C14: =IF($A14="","",EDATE($B$5,$A14*'Súpis dlhov'!$B$5)) -> 45744 | D14: =IF($A14="","",$F13) -> 52531.25 | E14: =IF($A14="","",$D14*$B$8) -> 1313.2812 | F14: =IF($A14="","",$D14+$E14) -> 53844.531
A15: =IF(4<=$B$7,4,"") -> 4 | B15: =IF($A15="","",EDATE($B$5,($A15-1)*'Súpis dlhov'!$B$5)) -> 45744 | C15: =IF($A15="","",EDATE($B$5,$A15*'Súpis dlhov'!$B$5)) -> 45836 | D15: =IF($A15="","",$F14) -> 53844.531 | E15: =IF($A15="","",$D15*$B$8) -> 1346.1133 | F15: =IF($A15="","",$D15+$E15) -> 55190.645
A16: =IF(5<=$B$7,5,"") -> 5 | B16: =IF($A16="","",EDATE($B$5,($A16-1)*'Súpis dlhov'!$B$5)) -> 45836 | C16: =IF($A16="","",EDATE($B$5,$A16*'Súpis dlhov'!$B$5)) -> 45928 | D16: =IF($A16="","",$F15) -> 55190.645 | E16: =IF($A16="","",$D16*$B$8) -> 1379.7661 | F16: =IF($A16="","",$D16+$E16) -> 56570.411
A17: =IF(6<=$B$7,6,"") -> 6 | B17: =IF($A17="","",EDATE($B$5,($A17-1)*'Súpis dlhov'!$B$5)) -> 45928 | C17: =IF($A17="","",EDATE($B$5,$A17*'Súpis dlhov'!$B$5)) -> 46019 | D17: =IF($A17="","",$F16) -> 56570.411 | E17: =IF($A17="","",$D17*$B$8) -> 1414.2603 | F17: =IF($A17="","",$D17+$E17) -> 57984.671
A18: =IF(7<=$B$7,7,"") -> 7 | B18: =IF($A18="","",EDATE($B$5,($A18-1)*'Súpis dlhov'!$B$5)) -> 46019 | C18: =IF($A18="","",EDATE($B$5,$A18*'Súpis dlhov'!$B$5)) -> 46109 | D18: =IF($A18="","",$F17) -> 57984.671 | E18: =IF($A18="","",$D18*$B$8) -> 1449.6168 | F18: =IF($A18="","",$D18+$E18) -> 59434.288
A19: =IF(8<=$B$7,8,"") -> 8 | B19: =IF($A19="","",EDATE($B$5,($A19-1)*'Súpis dlhov'!$B$5)) -> 46109 | C19: =IF($A19="","",EDATE($B$5,$A19*'Súpis dlhov'!$B$5)) -> 46201 | D19: =IF($A19="","",$F18) -> 59434.288 | E19: =IF($A19="","",$D19*$B$8) -> 1485.8572 | F19: =IF($A19="","",$D19+$E19) -> 60920.145
A20: =IF(9<=$B$7,9,"") -> 9 | B20: =IF($A20="","",EDATE($B$5,($A20-1)*'Súpis dlhov'!$B$5)) -> 46201 | C20: =IF($A20="","",EDATE($B$5,$A20*'Súpis dlhov'!$B$5)) -> 46293 | D20: =IF($A20="","",$F19) -> 60920.145 | E20: =IF($A20="","",$D20*$B$8) -> 1523.0036 | F20: =IF($A20="","",$D20+$E20) -> 62443.148
A21: =IF(10<=$B$7,10,"") | B21: =IF($A21="","",EDATE($B$5,($A21-1)*'Súpis dlhov'!$B$5)) | C21: =IF($A21="","",EDATE($B$5,$A21*'Súpis dlhov'!$B$5)) | D21: =IF($A21="","",$F20) | E21: =IF($A21="","",$D21*$B$8) | F21: =IF($A21="","",$D21+$E21)
A22: =IF(11<=$B$7,11,"") | B22: =IF($A22="","",EDATE($B$5,($A22-1)*'Súpis dlhov'!$B$5)) | C22: =IF($A22="","",EDATE($B$5,$A22*'Súpis dlhov'!$B$5)) | D22: =IF($A22="","",$F21) | E22: =IF($A22="","",$D22*$B$8) | F22: =IF($A22="","",$D22+$E22)
A23: =IF(12<=$B$7,12,"") | B23: =IF($A23="","",EDATE($B$5,($A23-1)*'Súpis dlhov'!$B$5)) | C23: =IF($A23="","",EDATE($B$5,$A23*'Súpis dlhov'!$B$5)) | D23: =IF($A23="","",$F22) | E23: =IF($A23="","",$D23*$B$8) | F23: =IF($A23="","",$D23+$E23)
A24: =IF(13<=$B$7,13,"") | B24: =IF($A24="","",EDATE($B$5,($A24-1)*'Súpis dlhov'!$B$5)) | C24: =IF($A24="","",EDATE($B$5,$A24*'Súpis dlhov'!$B$5)) | D24: =IF($A24="","",$F23) | E24: =IF($A24="","",$D24*$B$8) | F24: =IF($A24="","",$D24+$E24)
A25: =IF(14<=$B$7,14,"") | B25: =IF($A25="","",EDATE($B$5,($A25-1)*'Súpis dlhov'!$B$5)) | C25: =IF($A25="","",EDATE($B$5,$A25*'Súpis dlhov'!$B$5)) | D25: =IF($A25="","",$F24) | E25: =IF($A25="","",$D25*$B$8) | F25: =IF($A25="","",$D25+$E25)
A26: =IF(15<=$B$7,15,"") | B26: =IF($A26="","",EDATE($B$5,($A26-1)*'Súpis dlhov'!$B$5)) | C26: =IF($A26="","",EDATE($B$5,$A26*'Súpis dlhov'!$B$5)) | D26: =IF($A26="","",$F25) | E26: =IF($A26="","",$D26*$B$8) | F26: =IF($A26="","",$D26+$E26)
A27: =IF(16<=$B$7,16,"") | B27: =IF($A27="","",EDATE($B$5,($A27-1)*'Súpis dlhov'!$B$5)) | C27: =IF($A27="","",EDATE($B$5,$A27*'Súpis dlhov'!$B$5)) | D27: =IF($A27="","",$F26) | E27: =IF($A27="","",$D27*$B$8) | F27: =IF($A27="","",$D27+$E27)
A28: =IF(17<=$B$7,17,"") | B28: =IF($A28="","",EDATE($B$5,($A28-1)*'Súpis dlhov'!$B$5)) | C28: =IF($A28="","",EDATE($B$5,$A28*'Súpis dlhov'!$B$5)) | D28: =IF($A28="","",$F27) | E28: =IF($A28="","",$D28*$B$8) | F28: =IF($A28="","",$D28+$E28)
A29: =IF(18<=$B$7,18,"") | B29: =IF($A29="","",EDATE($B$5,($A29-1)*'Súpis dlhov'!$B$5)) | C29: =IF($A29="","",EDATE($B$5,$A29*'Súpis dlhov'!$B$5)) | D29: =IF($A29="","",$F28) | E29: =IF($A29="","",$D29*$B$8) | F29: =IF($A29="","",$D29+$E29)
A30: =IF(19<=$B$7,19,"") | B30: =IF($A30="","",EDATE($B$5,($A30-1)*'Súpis dlhov'!$B$5)) | C30: =IF($A30="","",EDATE($B$5,$A30*'Súpis dlhov'!$B$5)) | D30: =IF($A30="","",$F29) | E30: =IF($A30="","",$D30*$B$8) | F30: =IF($A30="","",$D30+$E30)
A31: =IF(20<=$B$7,20,"") | B31: =IF($A31="","",EDATE($B$5,($A31-1)*'Súpis dlhov'!$B$5)) | C31: =IF($A31="","",EDATE($B$5,$A31*'Súpis dlhov'!$B$5)) | D31: =IF($A31="","",$F30) | E31: =IF($A31="","",$D31*$B$8) | F31: =IF($A31="","",$D31+$E31)
A32: =IF(21<=$B$7,21,"") | B32: =IF($A32="","",EDATE($B$5,($A32-1)*'Súpis dlhov'!$B$5)) | C32: =IF($A32="","",EDATE($B$5,$A32*'Súpis dlhov'!$B$5)) | D32: =IF($A32="","",$F31) | E32: =IF($A32="","",$D32*$B$8) | F32: =IF($A32="","",$D32+$E32)
A33: =IF(22<=$B$7,22,"") | B33: =IF($A33="","",EDATE($B$5,($A33-1)*'Súpis dlhov'!$B$5)) | C33: =IF($A33="","",EDATE($B$5,$A33*'Súpis dlhov'!$B$5)) | D33: =IF($A33="","",$F32) | E33: =IF($A33="","",$D33*$B$8) | F33: =IF($A33="","",$D33+$E33)
A34: =IF(23<=$B$7,23,"") | B34: =IF($A34="","",EDATE($B$5,($A34-1)*'Súpis dlhov'!$B$5)) | C34: =IF($A34="","",EDATE($B$5,$A34*'Súpis dlhov'!$B$5)) | D34: =IF($A34="","",$F33) | E34: =IF($A34="","",$D34*$B$8) | F34: =IF($A34="","",$D34+$E34)
A35: =IF(24<=$B$7,24,"") | B35: =IF($A35="","",EDATE($B$5,($A35-1)*'Súpis dlhov'!$B$5)) | C35: =IF($A35="","",EDATE($B$5,$A35*'Súpis dlhov'!$B$5)) | D35: =IF($A35="","",$F34) | E35: =IF($A35="","",$D35*$B$8) | F35: =IF($A35="","",$D35+$E35)
A36: =IF(25<=$B$7,25,"") | B36: =IF($A36="","",EDATE($B$5,($A36-1)*'Súpis dlhov'!$B$5)) | C36: =IF($A36="","",EDATE($B$5,$A36*'Súpis dlhov'!$B$5)) | D36: =IF($A36="","",$F35) | E36: =IF($A36="","",$D36*$B$8) | F36: =IF($A36="","",$D36+$E36)
A37: =IF(26<=$B$7,26,"") | B37: =IF($A37="","",EDATE($B$5,($A37-1)*'Súpis dlhov'!$B$5)) | C37: =IF($A37="","",EDATE($B$5,$A37*'Súpis dlhov'!$B$5)) | D37: =IF($A37="","",$F36) | E37: =IF($A37="","",$D37*$B$8) | F37: =IF($A37="","",$D37+$E37)
A38: =IF(27<=$B$7,27,"") | B38: =IF($A38="","",EDATE($B$5,($A38-1)*'Súpis dlhov'!$B$5)) | C38: =IF($A38="","",EDATE($B$5,$A38*'Súpis dlhov'!$B$5)) | D38: =IF($A38="","",$F37) | E38: =IF($A38="","",$D38*$B$8) | F38: =IF($A38="","",$D38+$E38)
A39: =IF(28<=$B$7,28,"") | B39: =IF($A39="","",EDATE($B$5,($A39-1)*'Súpis dlhov'!$B$5)) | C39: =IF($A39="","",EDATE($B$5,$A39*'Súpis dlhov'!$B$5)) | D39: =IF($A39="","",$F38) | E39: =IF($A39="","",$D39*$B$8) | F39: =IF($A39="","",$D39+$E39)
A40: =IF(29<=$B$7,29,"") | B40: =IF($A40="","",EDATE($B$5,($A40-1)*'Súpis dlhov'!$B$5)) | C40: =IF($A40="","",EDATE($B$5,$A40*'Súpis dlhov'!$B$5)) | D40: =IF($A40="","",$F39) | E40: =IF($A40="","",$D40*$B$8) | F40: =IF($A40="","",$D40+$E40)
A41: =IF(30<=$B$7,30,"") | B41: =IF($A41="","",EDATE($B$5,($A41-1)*'Súpis dlhov'!$B$5)) | C41: =IF($A41="","",EDATE($B$5,$A41*'Súpis dlhov'!$B$5)) | D41: =IF($A41="","",$F40) | E41: =IF($A41="","",$D41*$B$8) | F41: =IF($A41="","",$D41+$E41)
A42: =IF(31<=$B$7,31,"") | B42: =IF($A42="","",EDATE($B$5,($A42-1)*'Súpis dlhov'!$B$5)) | C42: =IF($A42="","",EDATE($B$5,$A42*'Súpis dlhov'!$B$5)) | D42: =IF($A42="","",$F41) | E42: =IF($A42="","",$D42*$B$8) | F42: =IF($A42="","",$D42+$E42)
...
